IssueComment
  { issueCommentUpdatedAt = 2014 (-04) (-04) 17 : 38 : 49 UTC
  , issueCommentUser =
      SimpleUser
        { simpleUserId = Id 5043
        , simpleUserLogin = N "thelinuxlich"
        , simpleUserAvatarUrl =
            "https://avatars.githubusercontent.com/u/5043?v=3"
        , simpleUserUrl = "https://api.github.com/users/thelinuxlich"
        , simpleUserType = OwnerUser
        }
  , issueCommentUrl =
      "https://api.github.com/repos/rethinkdb/docs/issues/comments/39591191"
  , issueCommentHtmlUrl =
      "https://github.com/rethinkdb/docs/issues/74#issuecomment-39591191"
  , issueCommentCreatedAt = 2014 (-04) (-04) 17 : 38 : 49 UTC
  , issueCommentBody =
      "I'm still getting error when running `pip install rethinkdb` on Archlinux with Python 3.4"
  , issueCommentId = 39591191
  }